<?xml version="1.0" ?>
<!-- =================================================================================== -->
<!-- |    This document was autogenerated by xacro from braccio_arm.urdf               | -->
<!-- |    EDITING THIS FILE BY HAND IS NOT RECOMMENDED                                 | -->
<!-- =================================================================================== -->
<!-- =================================================================================== -->
<!-- |    This document was autogenerated by xacro from src/braccio_arduino_ros_rviz/urdf/braccio_arm.xacro | -->
<!-- |    EDITING THIS FILE BY HAND IS NOT RECOMMENDED                                 | -->
<!-- =================================================================================== -->
<robot name="braccio" xmlns:xacro="http://www.ros.org/wiki/xacro">

  <xacro:property name="camera_link" value="0.05" /> <!-- Size of square 'camera' box -->
  <xacro:property name="damping_value" value="0.15"/>
  <xacro:property name="friction_value" value="0.025"/>

<xacro:property name="kinect_box_length" value="0.073" />
<xacro:property name="kinect_box_width" value="0.276" />
<xacro:property name="kinect_box_height" value="0.072" />
<xacro:property name="kinect_box_mass" value="0.1" />

<xacro:macro name="inertial_matrix_cuboid" params="mass box_length box_width">
               <inertial>
                       <mass value="${mass}" />
                       <inertia ixx="${mass/12*(box_length*box_length)}" 
                                ixy = "0" ixz = "0"
                                iyy="${mass/12*(box_width*box_width)}" iyz = "0"
                                izz="${mass/12*(box_length*box_length + box_width*box_width)}" />
               </inertial>
</xacro:macro>

<xacro:macro name="transmission_block" params="joint_name idx">
	  <transmission name="tran_${idx}">
	    <type>transmission_interface/SimpleTransmission</type>
	    <joint name="${joint_name}">
	      <hardwareInterface>hardware_interface/EffortJointInterface</hardwareInterface>
	    </joint>
	    <actuator name="motor__${idx}">
	      <hardwareInterface>hardware_interface/EffortJointInterface</hardwareInterface>
	      <mechanicalReduction>1</mechanicalReduction>
	    </actuator>
	  </transmission>
</xacro:macro>

<link name="world"/>

<joint name="world_joint" type="fixed">
    <parent link="world"/>
    <child link="base_link"/>
  </joint>

    <link name="base_link">
    <visual>
      <geometry>
	<cylinder length="0.01" radius=".053" />
      </geometry>
      <material name="black"/>
      <origin rpy="0 0 0" xyz="0 0 0"/>
    </visual>
    <inertial>
      <mass value="2"/>
	<inertia ixx="0.015" ixy="0" ixz="0" iyy="0.00666666666667" iyz="0" izz="0.0216666666667"/>
    </inertial>
  </link>

    <link name="camera_link" />

  <joint name="camera_joint" type="fixed">
	<origin xyz="0 0 1.1" rpy="0 0 0"/>	
    <parent link="base_link"/>
    <child link="camera_link"/>
  </joint>
  
  <link name="braccio_base_link">
    <visual>
      <geometry>
        <mesh filename="package://braccio_arm/stl/braccio_base.stl" scale="0.001 0.001 0.001"/>
      </geometry>
      <material name="orange"/>
      <origin rpy="0 0 3.1416" xyz="0 0.004 0" />
    </visual>
    <inertial>
      <mass value="2"/>
      <inertia ixx="0.015" ixy="0" ixz="0" iyy="0.00666666666667" iyz="0" izz="0.0216666666667"/>
    </inertial>
    <collision>
      <origin rpy="0 0 3.1416" xyz="0 0.004 0"/>
      <geometry>
        <mesh filename="package://braccio_arm/stl/braccio_base.stl" scale="0.001 0.001 0.001"/>
      </geometry>
    </collision>
  </link>
  <link name="shoulder_link">
    <visual>
      <geometry>
        <mesh filename="package://braccio_arm/stl/braccio_shoulder.stl" scale="0.001 0.001 0.001"/>
      </geometry>
      <material name="orange"/>
      <origin rpy="0 0 0" xyz="-0.0045 0.0055 -0.026"/>
    </visual>
    <inertial>
      <mass value="0.1"/>
      <inertia ixx="0.000348958333333" ixy="0" ixz="0" iyy="0.000348958333333" iyz="0" izz="3.125e-05"/>
    </inertial>
    <collision>
      <origin rpy="0 0 0" xyz="-0.0045 0.0055 -0.026"/>
      <geometry>
        <mesh filename="package://braccio_arm/stl/braccio_base.stl" scale="0.001 0.001 0.001"/>
      </geometry>
    </collision>
  </link>
  <link name="elbow_link">
    <visual>
      <geometry>
        <mesh filename="package://braccio_arm/stl/braccio_elbow.stl" scale="0.001 0.001 0.001"/>
      </geometry>
      <material name="orange"/>
      <origin rpy="0 0 0" xyz="-0.0045 0.005 -0.025"/>
    </visual>
    <inertial>
      <mass value="0.1"/>
      <inertia ixx="0.000348958333333" ixy="0" ixz="0" iyy="0.000348958333333" iyz="0" izz="3.125e-05"/>
    </inertial>
    <collision>
      <origin rpy="0 0 0" xyz="-0.0045 0.005 -0.025"/>
      <geometry>
        <mesh filename="package://braccio_arm/stl/braccio_elbow.stl" scale="0.001 0.001 0.001"/>
      </geometry>
    </collision>
  </link>
  <link name="wrist_pitch_link">
    <visual>
      <geometry>
        <mesh filename="package://braccio_arm/stl/braccio_wrist_pitch.stl" scale="0.001 0.001 0.001"/>
      </geometry>
      <material name="orange"/>
      <origin rpy="0 0 0" xyz="0.003 -0.0004 -0.024"/>
    </visual>
    <inertial>
      <mass value="0.1"/>
      <inertia ixx="0.000348958333333" ixy="0" ixz="0" iyy="0.000348958333333" iyz="0" izz="3.125e-05"/>
    </inertial>
    <collision>
      <origin rpy="0 0 0" xyz="0.003 -0.0004 -0.024"/>
      <geometry>
        <mesh filename="package://braccio_arm/stl/braccio_wrist_pitch.stl" scale="0.001 0.001 0.001"/>
      </geometry>
    </collision>
  </link>
  <link name="wrist_roll_link">
    <visual>
      <geometry>
        <mesh filename="package://braccio_arm/stl/braccio_wrist_roll.stl" scale="0.001 0.001 0.001"/>
      </geometry>
      <material name="white"/>
      <origin rpy="0 0 0" xyz="0.006 0 0.0"/>
    </visual>
    <inertial>
      <mass value="0.1"/>
      <inertia ixx="0.000348958333333" ixy="0" ixz="0" iyy="0.000348958333333" iyz="0" izz="3.125e-05"/>
    </inertial>
    <collision>
      <origin rpy="0 0 0" xyz="0.006 0 0.0"/>
      <geometry>
        <mesh filename="package://braccio_arm/stl/braccio_wrist_roll.stl" scale="0.001 0.001 0.001"/>
      </geometry>
    </collision>
  </link>
  <link name="left_gripper_link">
    <visual>
      <geometry>
        <mesh filename="package://braccio_arm/stl/braccio_left_gripper.stl" scale="0.001 0.001 0.001"/>
      </geometry>
      <material name="white"/>
      <origin rpy="0 1.5708 0" xyz="0 -0.012 0"/>
    </visual>
    <inertial>
      <mass value="0.1"/>
      <inertia ixx="0.000348958333333" ixy="0" ixz="0" iyy="0.000348958333333" iyz="0" izz="3.125e-05"/>
    </inertial>
    <collision>
      <origin rpy="0 1.5708 0" xyz="0 -0.012 0"/>
      <geometry>
        <mesh filename="package://braccio_arm/stl/braccio_left_gripper.stl" scale="0.001 0.001 0.001"/>
      </geometry>
    </collision>
  </link>
  <link name="right_gripper_link">
    <visual>
      <geometry>
        <mesh filename="package://braccio_arm/stl/braccio_right_gripper.stl" scale="0.001 0.001 0.001"/>
      </geometry>
      <material name="white"/>
      <origin rpy="0 1.5708 0" xyz="0 -0.012 0.010"/>
    </visual>
    <inertial>
      <mass value="0.1"/>
      <inertia ixx="0.000348958333333" ixy="0" ixz="0" iyy="0.000348958333333" iyz="0" izz="3.125e-05"/>
    </inertial>
    <collision>
      <origin rpy="0 1.5708 0" xyz="0 -0.012 0.010"/>
      <geometry>
        <mesh filename="package://braccio_arm/stl/braccio_right_gripper.stl" scale="0.001 0.001 0.001"/>
      </geometry>
    </collision>
  </link>
  <joint name="base_joint" type="revolute">
    <axis xyz="0 0 1"/>
    <limit effort="1000.0" lower="0.0" upper="3.1416" velocity="1.0"/>
    <origin rpy="0 0 0" xyz="0 0 0"/>
    <parent link="base_link"/>
    <child link="braccio_base_link"/>
    <dynamics damping="${damping_value}" friction="${friction_value}"/>
  </joint>
  <joint name="shoulder_joint" type="revolute">
    <axis xyz="1 0 0"/>
    <limit effort="1000.0" lower="0.2618" upper="2.8798" velocity="1.0"/>
    <origin rpy="-1.5708 0 0" xyz="0 -.002 0.072"/>
    <parent link="braccio_base_link"/>
    <child link="shoulder_link"/>
    <dynamics damping="${damping_value}" friction="${friction_value}"/>
  </joint>
  <joint name="elbow_joint" type="revolute">
    <axis xyz="1 0 0"/>
    <limit effort="1000.0" lower="0" upper="3.1416" velocity="1.0"/>
    <origin rpy="-1.5708 0 0" xyz="0 0 0.125"/>
    <parent link="shoulder_link"/>
    <child link="elbow_link"/>
    <dynamics damping="${damping_value}" friction="${friction_value}"/>
  </joint>
  <joint name="wrist_pitch_joint" type="revolute">
    <axis xyz="1 0 0"/>
    <limit effort="1000.0" lower="0" upper="3.1416" velocity="1.0"/>
    <origin rpy="-1.5708 0 0" xyz="0 0 0.125"/>
    <parent link="elbow_link"/>
    <child link="wrist_pitch_link"/>
    <dynamics damping="${damping_value}" friction="${friction_value}"/>
  </joint>
  <joint name="wrist_roll_joint" type="revolute">
    <axis xyz="0 0 -1"/>
    <limit effort="1000.0" lower="0.0" upper="3.1416" velocity="1.0"/>
    <origin rpy="0 0 1.5708" xyz="0 0.0 0.06"/>
    <parent link="wrist_pitch_link"/>
    <child link="wrist_roll_link"/>
    <dynamics damping="${damping_value}" friction="${friction_value}"/>
  </joint>
  <joint name="gripper_joint" type="revolute">
    <axis xyz="0 -1 0"/>
    <limit effort="1000.0" lower="0.1750" upper="1.2741" velocity="1.0"/>
    <origin rpy="0 -0.2967 0" xyz="0.010 0 0.03"/>
    <parent link="wrist_roll_link"/>
    <child link="right_gripper_link"/>
    <dynamics damping="${damping_value}" friction="${friction_value}"/>
  </joint>
  <joint name="sub_gripper_joint" type="revolute">
    <axis xyz="0 1 0"/>
    <mimic joint="gripper_joint"/>
    <limit effort="1000.0" lower="1.2741" upper="2.3732" velocity="1.0"/>
    <origin rpy="0 3.4383 0" xyz="-0.010 0 0.03"/>
    <parent link="wrist_roll_link"/>
    <child link="left_gripper_link"/>
    <dynamics damping="${damping_value}" friction="${friction_value}"/>
  </joint>
  <material name="orange">
    <color rgba="0.57 0.17 0.0 1"/>
  </material>
  <material name="white">
    <color rgba="0.8 0.8 0.8 1.0"/>
  </material>
  <material name="black">
    <color rgba="0 0 0 0.50"/>
  </material>


   <xacro:transmission_block joint_name="base_joint" idx="1"/>
   <xacro:transmission_block joint_name="shoulder_joint" idx="2"/>
   <xacro:transmission_block joint_name="elbow_joint" idx="3"/>
   <xacro:transmission_block joint_name="wrist_pitch_joint" idx="4"/>
   <xacro:transmission_block joint_name="wrist_roll_joint" idx="5"/>
   <xacro:transmission_block joint_name="gripper_joint" idx="6"/>
   <xacro:transmission_block joint_name="sub_gripper_joint" idx="7"/>

<gazebo>
  <plugin name="gazebo_ros_control" filename="libgazebo_ros_control.so">
    <robotNamespace>/braccio</robotNamespace>
  </plugin>
</gazebo>

</robot>
